<?xml version="1.0"?>
<robot name="iris" xmlns:xacro="http://ros.org/wiki/xacro">
    <material name="gray">
        <color rgba="0.2 0.2 0.2 1"/>
    </material>

    <material name="yellow">
        <color rgba="0.7 0.7 0 1"/>
    </material>

    <material name="orange">
        <color rgba="0.7 0.2 0 1"/>
    </material>

    <!-- Base -->
    <link name="base_link"/>

    <link name="chassis_link">
        <inertial>
            <mass value="1.5" />
            <origin xyz="0 0 0"/>
            <inertia ixx="0.029125" ixy="0.0" ixz="0.0" iyy="0.029125" iyz="0.0" izz="0.055225" />
        </inertial>
        <visual>
            <origin xyz="0 0 0" rpy="0 0 0"/>
            <geometry>
                <mesh filename="package://uav_inspections_ros2/meshes/iris.stl"/>
            </geometry>
            <material name="gray"/>
        </visual>
        <collision>
            <origin xyz="0 0 0" rpy="0 0 0"/>
            <geometry>
                <mesh filename="package://uav_inspections_ros2/meshes/iris.stl"/>
            </geometry>
        </collision>
    </link>

    <joint name="chassis_joint" type="fixed">
    <origin xyz="0 0 0"/>
    <parent link="base_link"/>
    <child link="chassis_link"/>
    </joint>

    <!-- Rotors -->
    <link name="rotor_0">
        <inertial>
            <mass value="0.005" />
            <origin xyz="0 0 0"/>
            <inertia ixx="9.75e-07" ixy="0.0" ixz="0.0" iyy="0.000273104" iyz="0.0" izz="0.000273104" />
        </inertial>
        <visual>
            <origin xyz="0 0 0" rpy="0 0 0"/>
            <geometry>
                <mesh filename="package://uav_inspections_ros2/meshes/iris_prop_ccw.stl"/>
            </geometry>
            <material name="orange"/>
        </visual>
        <collision>
            <origin xyz="0 0 0" rpy="0 0 0"/>
            <geometry>
                <mesh filename="package://uav_inspections_ros2/meshes/iris_prop_ccw.stl"/>
            </geometry>
        </collision>
    </link>

    <joint name="rotor_0_joint" type="continuous">
        <axis xyz="0 0 1"/>
        <origin xyz="0.13 -0.22 0.023" rpy="0 0 0" />
        <parent link="base_link"/>
        <child link="rotor_0" />
    </joint>

    <link name="rotor_1">
        <inertial>
            <mass value="0.005" />
            <origin xyz="0 0 0"/>
            <inertia ixx="9.75e-07" ixy="0.0" ixz="0.0" iyy="0.000273104" iyz="0.0" izz="0.000273104" />
        </inertial>
        <visual>
            <origin xyz="0 0 0" rpy="0 0 0"/>
            <geometry>
                <mesh filename="package://uav_inspections_ros2/meshes/iris_prop_ccw.stl"/>
            </geometry>
            <material name="yellow"/>
        </visual>
        <collision>
            <origin xyz="0 0 0" rpy="0 0 0"/>
            <geometry>
                <mesh filename="package://uav_inspections_ros2/meshes/iris_prop_ccw.stl"/>
            </geometry>
        </collision>
    </link>

    <joint name="rotor_1_joint" type="continuous">
        <axis xyz="0 0 1"/>
        <origin xyz="-0.13 0.22 0.023" rpy="0 0 0" />
        <parent link="base_link"/>
        <child link="rotor_1" />
    </joint>

    <link name="rotor_2">
        <inertial>
            <mass value="0.005" />
            <origin xyz="0 0 0"/>
            <inertia ixx="9.75e-07" ixy="0.0" ixz="0.0" iyy="0.000273104" iyz="0.0" izz="0.000273104" />
        </inertial>
        <visual>
            <origin xyz="0 0 0" rpy="0 0 0"/>
            <geometry>
                <mesh filename="package://uav_inspections_ros2/meshes/iris_prop_cw.stl"/>
            </geometry>
            <material name="orange"/>
        </visual>
        <collision>
            <origin xyz="0 0 0" rpy="0 0 0"/>
            <geometry>
                <mesh filename="package://uav_inspections_ros2/meshes/iris_prop_cw.stl"/>
            </geometry>
        </collision>
    </link>

    <joint name="rotor_2_joint" type="continuous">
        <axis xyz="0 0 1"/>
        <origin xyz="0.13 0.22 0.023" rpy="0 0 0" />
        <parent link="base_link"/>
        <child link="rotor_2" />
    </joint>

    <link name="rotor_3">
        <inertial>
            <mass value="0.005" />
            <origin xyz="0 0 0"/>
            <inertia ixx="9.75e-07" ixy="0.0" ixz="0.0" iyy="0.000273104" iyz="0.0" izz="0.000273104" />
        </inertial>
        <visual>
            <origin xyz="0 0 0" rpy="0 0 0"/>
            <geometry>
                <mesh filename="package://uav_inspections_ros2/meshes/iris_prop_cw.stl"/>
            </geometry>
            <material name="yellow"/>
        </visual>
        <collision>
            <origin xyz="0 0 0" rpy="0 0 0"/>
            <geometry>
                <mesh filename="package://uav_inspections_ros2/meshes/iris_prop_cw.stl"/>
            </geometry>
        </collision>
    </link>

    <joint name="rotor_3_joint" type="continuous">
        <axis xyz="0 0 1"/>
        <origin xyz="-0.13 -0.22 0.023" rpy="0 0 0" />
        <parent link="base_link"/>
        <child link="rotor_3" />
    </joint>

    <!-- Sensors -->
    <link name="camera_link"/>

    <joint name="camera_joint" type="fixed">
      <origin xyz="0.05 0 -0.05" rpy="0 0 0" />
      <parent link="base_link"/>
      <child link="camera_link" />
    </joint>

    <link name="imu_link"/>

    <joint name="imu_joint" type="fixed">
      <origin xyz="0 0 0" rpy="0 0 0" />
      <parent link="base_link"/>
      <child link="imu_link" />
    </joint>

    <link name="gps_link"/>

    <joint name="gps_joint" type="fixed">
      <origin xyz="0 0 0" rpy="0 0 0" />
      <parent link="base_link"/>
      <child link="gps_link" />
    </joint>
    
    <link name="magnetometer_link"/>

    <joint name="magnetometer_joint" type="fixed">
      <origin xyz="0 0 0" rpy="0 0 0" />
      <parent link="base_link"/>
      <child link="magnetometer_link" />
    </joint>

    <link name="barometer_link"/>

    <joint name="barometer_joint" type="fixed">
      <origin xyz="0 0 0" rpy="0 0 0" />
      <parent link="base_link"/>
      <child link="barometer_link" />
    </joint>


    <!-- Gazebo -->
    <gazebo reference="chassis_link">
       <material>Gazebo/Grey</material>
    </gazebo>

    <gazebo reference="rotor_0">
       <material>Gazebo/Orange</material>
    </gazebo>

    <gazebo reference="rotor_1">
       <material>Gazebo/Yellow</material>
    </gazebo>

    <gazebo reference="rotor_2">
       <material>Gazebo/Orange</material>
    </gazebo>

    <gazebo reference="rotor_3">
       <material>Gazebo/Yellow</material>
    </gazebo>

    <gazebo>
    <plugin name="ground_truth_odom" filename="libgazebo_ros_p3d.so">
        <ros>
            <argument>odom:=odom/perfect</argument>
        </ros>
        <body_name>base_link</body_name>
        <frame_name>chassis_link</frame_name>
        <update_rate>1</update_rate>
        <xyz_offset>0 0 0</xyz_offset>
        <rpy_offset>0 0 0</rpy_offset>
        <gaussian_noise>0</gaussian_noise>
    </plugin>
    </gazebo>


    <gazebo reference="camera_link">
    <sensor type="depth" name="camera">
        <always_on>true</always_on>
        <update_rate>30</update_rate>
      <camera name="camera">
        <horizontal_fov>1.2</horizontal_fov>
        <image>
          <width>640</width>
          <height>480</height>
          <format>R8G8B8</format>
        </image>
        <depth_camera>
        </depth_camera>
        <clip>
          <near>0.02</near>
          <far>100</far>
        </clip>
        <distortion>
          <k1>0.0</k1>
          <k2>0.0</k2>
          <k3>0.0</k3>
          <p1>0.0</p1>
          <p2>0.0</p2>
        </distortion>
      </camera>
      <plugin name="simulated_camera" filename="libgazebo_ros_camera.so">
        <camera_name>camera</camera_name>
        <frame_name>camera_link</frame_name>
        <hack_baseline>0.07</hack_baseline>
        <min_depth>0.001</min_depth>
      </plugin>
    </sensor>
    </gazebo>

    <gazebo reference="imu_link">
    <plugin name='rotors_gazebo_imu_plugin' filename='libgazebo_imu_plugin.so'>
      <robotNamespace/>
      <linkName>/imu_link</linkName>
      <imuTopic>/imu</imuTopic>
      <gyroscopeNoiseDensity>0.00018665</gyroscopeNoiseDensity>
      <gyroscopeRandomWalk>3.8785e-05</gyroscopeRandomWalk>
      <gyroscopeBiasCorrelationTime>1000.0</gyroscopeBiasCorrelationTime>
      <gyroscopeTurnOnBiasSigma>0.0087</gyroscopeTurnOnBiasSigma>
      <accelerometerNoiseDensity>0.00186</accelerometerNoiseDensity>
      <accelerometerRandomWalk>0.006</accelerometerRandomWalk>
      <accelerometerBiasCorrelationTime>300.0</accelerometerBiasCorrelationTime>
      <accelerometerTurnOnBiasSigma>0.196</accelerometerTurnOnBiasSigma>
    </plugin>
    <!-- <sensor name="imu" type="imu"> -->
    <!-- <always_on>true</always_on> -->
    <!-- <update_rate>30</update_rate> -->
    <!-- <plugin name="simulated_imu" filename="libgazebo_ros_imu_sensor.so"> -->
        <!-- <ros> -->
            <!-- <namespace>/imu</namespace> -->
            <!-- <argument>~/out:=data</argument> -->
         <!-- </ros> -->
        <!-- <frame_name>imu_link</frame_name> -->
    <!-- </plugin> -->
    <!-- </sensor> -->
    </gazebo>

    <gazebo reference="gps_link">
    <sensor name="gps" type="gps">
        <pose>0 0 0 0 0 0</pose>
        <update_rate>5.0</update_rate>
        <always_on>true</always_on>
        <visualize>false</visualize>
        <!-- GpsSensor noise currently not used -->
        <!-- <gps>
          <position_sensing>
            <horizontal>
              <noise type="gaussian_quantized">
                <mean>0</mean>
                <stddev>1</stddev>
                <bias_mean>3</bias_mean>
                <bias_stddev>1</bias_stddev>
                <precision>0.5</precision>
              </noise>
            </horizontal>
            <vertical>
              <noise type="gaussian_quantized">
                <mean>0</mean>
                <stddev>1</stddev>
                <bias_mean>3</bias_mean>
                <bias_stddev>1</bias_stddev>
                <precision>1.0</precision>
              </noise>
            </vertical>
          </position_sensing>
          <velocity_sensing>
            <horizontal>
              <noise type="gaussian_quantized">
                <mean>0</mean>
                <stddev>0.1</stddev>
                <bias_mean>0.1</bias_mean>
                <bias_stddev>0.1</bias_stddev>
                <precision>0.1</precision>
              </noise>
            </horizontal>
            <vertical>
              <noise type="gaussian_quantized">
                <mean>0</mean>
                <stddev>0.2</stddev>
                <bias_mean>0.2</bias_mean>
                <bias_stddev>0.2</bias_stddev>
                <precision>0.2</precision>
              </noise>
            </vertical>
          </velocity_sensing>
        </gps> -->
        <plugin name="gps_plugin" filename="libgazebo_gps_plugin.so">
          <robotNamespace></robotNamespace>
          <gpsNoise>true</gpsNoise>
          <gpsXYRandomWalk>2.0</gpsXYRandomWalk>
          <gpsZRandomWalk>4.0</gpsZRandomWalk>
          <gpsXYNoiseDensity>2.0e-4</gpsXYNoiseDensity>
          <gpsZNoiseDensity>4.0e-4</gpsZNoiseDensity>
          <gpsVXYNoiseDensity>0.2</gpsVXYNoiseDensity>
          <gpsVZNoiseDensity>0.4</gpsVZNoiseDensity>
        </plugin>
      </sensor>
    <!-- <sensor name="gps" type="gps"> -->
          <!-- <always_on>true</always_on> -->
          <!-- <update_rate>30</update_rate> -->
          <!-- <gps> -->
            <!-- <position_sensing> -->
              <!-- <horizontal> -->
                <!-- <noise type="gaussian"> -->
                  <!-- <mean>0.0</mean> -->
                  <!-- <stddev>2e-4</stddev> -->
                <!-- </noise> -->
              <!-- </horizontal> -->
              <!-- <vertical> -->
                <!-- <noise type="gaussian"> -->
                  <!-- <mean>0.0</mean> -->
                  <!-- <stddev>2e-4</stddev> -->
                <!-- </noise> -->
              <!-- </vertical> -->
            <!-- </position_sensing> -->
          <!-- </gps> -->
          <!-- <plugin name="simulated_gps" filename="libgazebo_ros_gps_sensor.so"> -->
            <!-- <ros> -->
              <!-- <namespace>/gps</namespace> -->
              <!-- <argument>~/out:=data</argument> -->
            <!-- </ros> -->
          <!-- </plugin> -->
        <!-- </sensor> -->
    </gazebo>


    <gazebo reference="rotor_0">
    <plugin name='front_right_motor_model' filename='libgazebo_motor_model.so'>
      <robotNamespace/>
      <jointName>rotor_0_joint</jointName>
      <linkName>rotor_0</linkName>
      <turningDirection>ccw</turningDirection>
      <timeConstantUp>0.0125</timeConstantUp>
      <timeConstantDown>0.025</timeConstantDown>
      <maxRotVelocity>1100</maxRotVelocity>
      <motorConstant>5.84e-06</motorConstant>
      <momentConstant>0.06</momentConstant>
      <commandSubTopic>/gazebo/command/motor_speed</commandSubTopic>
      <motorNumber>0</motorNumber>
      <rotorDragCoefficient>0.000175</rotorDragCoefficient>
      <rollingMomentCoefficient>1e-06</rollingMomentCoefficient>
      <motorSpeedPubTopic>/motor_speed/0</motorSpeedPubTopic>
      <rotorVelocitySlowdownSim>10</rotorVelocitySlowdownSim>
    </plugin>
    </gazebo>

    <gazebo reference="rotor_1">
    <plugin name='back_left_motor_model' filename='libgazebo_motor_model.so'>
      <robotNamespace/>
      <jointName>rotor_1_joint</jointName>
      <linkName>rotor_1</linkName>
      <turningDirection>ccw</turningDirection>
      <timeConstantUp>0.0125</timeConstantUp>
      <timeConstantDown>0.025</timeConstantDown>
      <maxRotVelocity>1100</maxRotVelocity>
      <motorConstant>5.84e-06</motorConstant>
      <momentConstant>0.06</momentConstant>
      <commandSubTopic>/gazebo/command/motor_speed</commandSubTopic>
      <motorNumber>1</motorNumber>
      <rotorDragCoefficient>0.000175</rotorDragCoefficient>
      <rollingMomentCoefficient>1e-06</rollingMomentCoefficient>
      <motorSpeedPubTopic>/motor_speed/1</motorSpeedPubTopic>
      <rotorVelocitySlowdownSim>10</rotorVelocitySlowdownSim>
    </plugin>
    </gazebo>

    <gazebo reference="rotor_2">
    <plugin name='front_left_motor_model' filename='libgazebo_motor_model.so'>
      <robotNamespace/>
      <jointName>rotor_2_joint</jointName>
      <linkName>rotor_2</linkName>
      <turningDirection>cw</turningDirection>
      <timeConstantUp>0.0125</timeConstantUp>
      <timeConstantDown>0.025</timeConstantDown>
      <maxRotVelocity>1100</maxRotVelocity>
      <motorConstant>5.84e-06</motorConstant>
      <momentConstant>0.06</momentConstant>
      <commandSubTopic>/gazebo/command/motor_speed</commandSubTopic>
      <motorNumber>2</motorNumber>
      <rotorDragCoefficient>0.000175</rotorDragCoefficient>
      <rollingMomentCoefficient>1e-06</rollingMomentCoefficient>
      <motorSpeedPubTopic>/motor_speed/2</motorSpeedPubTopic>
      <rotorVelocitySlowdownSim>10</rotorVelocitySlowdownSim>
    </plugin>
    </gazebo>

    <gazebo reference="rotor_3">
    <plugin name='back_right_motor_model' filename='libgazebo_motor_model.so'>
      <robotNamespace/>
      <jointName>rotor_3_joint</jointName>
      <linkName>rotor_3</linkName>
      <turningDirection>cw</turningDirection>
      <timeConstantUp>0.0125</timeConstantUp>
      <timeConstantDown>0.025</timeConstantDown>
      <maxRotVelocity>1100</maxRotVelocity>
      <motorConstant>5.84e-06</motorConstant>
      <momentConstant>0.06</momentConstant>
      <commandSubTopic>/gazebo/command/motor_speed</commandSubTopic>
      <motorNumber>3</motorNumber>
      <rotorDragCoefficient>0.000175</rotorDragCoefficient>
      <rollingMomentCoefficient>1e-06</rollingMomentCoefficient>
      <motorSpeedPubTopic>/motor_speed/3</motorSpeedPubTopic>
      <rotorVelocitySlowdownSim>10</rotorVelocitySlowdownSim>
    </plugin>
    </gazebo>

    <gazebo reference="barometer_link">
    <plugin name='barometer_plugin' filename='libgazebo_barometer_plugin.so'>
      <robotNamespace/>
      <pubRate>50</pubRate>
      <baroTopic>/baro</baroTopic>
      <baroDriftPaPerSec>0</baroDriftPaPerSec>
    </plugin>
    </gazebo>

    <gazebo reference="magnetometer_link">
    <plugin name='magnetometer_plugin' filename='libgazebo_magnetometer_plugin.so'>
      <robotNamespace/>
      <pubRate>100</pubRate>
      <noiseDensity>0.0004</noiseDensity>
      <randomWalk>6.4e-06</randomWalk>
      <biasCorrelationTime>600</biasCorrelationTime>
      <magTopic>/mag</magTopic>
    </plugin>
    </gazebo>

    <!-- Transmissions (not sure if needed yet)-->
  <!-- <transmission name="rotor_0_trans"> -->
    <!-- <type>transmission_interface/SimpleTransmission</type> -->
    <!-- <actuator name="rotor_0"> -->
      <!-- <mechanicalReduction>1</mechanicalReduction> -->
    <!-- </actuator> -->
    <!-- <joint name="rotor_0_joint"> -->
      <!-- <hardwareInterface>EffortJointInterface</hardwareInterface> -->
    <!-- </joint> -->
  <!-- </transmission> -->
  <!-- <transmission name="rotor_1_trans"> -->
    <!-- <type>transmission_interface/SimpleTransmission</type> -->
    <!-- <actuator name="rotor_1"> -->
      <!-- <mechanicalReduction>1</mechanicalReduction> -->
    <!-- </actuator> -->
    <!-- <joint name="rotor_1_joint"> -->
      <!-- <hardwareInterface>EffortJointInterface</hardwareInterface> -->
    <!-- </joint> -->
  <!-- </transmission> -->
  <!-- <transmission name="rotor_2_trans"> -->
    <!-- <type>transmission_interface/SimpleTransmission</type> -->
    <!-- <actuator name="rotor_2"> -->
      <!-- <mechanicalReduction>1</mechanicalReduction> -->
    <!-- </actuator> -->
    <!-- <joint name="rotor_2_joint"> -->
      <!-- <hardwareInterface>EffortJointInterface</hardwareInterface> -->
    <!-- </joint> -->
  <!-- </transmission> -->
  <!-- <transmission name="rotor_3_trans"> -->
    <!-- <type>transmission_interface/SimpleTransmission</type> -->
    <!-- <actuator name="rotor_3"> -->
      <!-- <mechanicalReduction>1</mechanicalReduction> -->
    <!-- </actuator> -->
    <!-- <joint name="rotor_3_joint"> -->
      <!-- <hardwareInterface>EffortJointInterface</hardwareInterface> -->
    <!-- </joint> -->
  <!-- </transmission> -->

    <gazebo>
    <plugin name='mavlink_interface' filename='libgazebo_mavlink_interface.so'>
      <robotNamespace/>
      <imuSubTopic>/imu</imuSubTopic>
      <gpsSubTopic>/gps</gpsSubTopic>
      <magSubTopic>/mag</magSubTopic>
      <baroSubTopic>/baro</baroSubTopic>
      <mavlink_addr>INADDR_ANY</mavlink_addr>
      <mavlink_udp_port>14560</mavlink_udp_port>
      <mavlink_tcp_port>4560</mavlink_tcp_port>
      <serialEnabled>false</serialEnabled>
      <serialDevice>/dev/ttyACM0</serialDevice>
      <baudRate>921600</baudRate>
      <qgc_addr>INADDR_ANY</qgc_addr>
      <qgc_udp_port>14550</qgc_udp_port>
      <sdk_addr>INADDR_ANY</sdk_addr>
      <sdk_udp_port>14540</sdk_udp_port>
      <hil_mode>false</hil_mode>
      <hil_state_level>false</hil_state_level>
      <vehicle_is_tailsitter>false</vehicle_is_tailsitter>
      <send_vision_estimation>true</send_vision_estimation>
      <send_odometry>false</send_odometry>
      <enable_lockstep>false</enable_lockstep>
      <use_tcp>true</use_tcp>
      <motorSpeedCommandPubTopic>/gazebo/command/motor_speed</motorSpeedCommandPubTopic>
      <control_channels>
        <channel name='rotor1'>
          <input_index>0</input_index>
          <input_offset>0</input_offset>
          <input_scaling>1000</input_scaling>
          <zero_position_disarmed>0</zero_position_disarmed>
          <zero_position_armed>100</zero_position_armed>
          <joint_control_type>velocity</joint_control_type>
        </channel>
        <channel name='rotor2'>
          <input_index>1</input_index>
          <input_offset>0</input_offset>
          <input_scaling>1000</input_scaling>
          <zero_position_disarmed>0</zero_position_disarmed>
          <zero_position_armed>100</zero_position_armed>
          <joint_control_type>velocity</joint_control_type>
        </channel>
        <channel name='rotor3'>
          <input_index>2</input_index>
          <input_offset>0</input_offset>
          <input_scaling>1000</input_scaling>
          <zero_position_disarmed>0</zero_position_disarmed>
          <zero_position_armed>100</zero_position_armed>
          <joint_control_type>velocity</joint_control_type>
        </channel>
        <channel name='rotor4'>
          <input_index>3</input_index>
          <input_offset>0</input_offset>
          <input_scaling>1000</input_scaling>
          <zero_position_disarmed>0</zero_position_disarmed>
          <zero_position_armed>100</zero_position_armed>
          <joint_control_type>velocity</joint_control_type>
        </channel>
      </control_channels>
    </plugin>
    <!-- <plugin name='rosbag' filename='libgazebo_multirotor_base_plugin.so'> -->
      <!-- <robotNamespace/> -->
      <!-- <linkName>base_link</linkName> -->
      <!-- <rotorVelocitySlowdownSim>10</rotorVelocitySlowdownSim> -->
    <!-- </plugin> -->
    </gazebo>

</robot>
